[2025-10-16 10:40:05,490][flwr][WARNING] - DEPRECATED FEATURE: flwr.simulation.start_simulation() is deprecated.
	Instead, use the `flwr run` CLI command to start a local simulation in your Flower app, as shown for example below:

		$ flwr new  # Create a new Flower app from a template

		$ flwr run  # Run the Flower app in Simulation Mode

	Using `start_simulation()` is deprecated.

            This is a deprecated feature. It will be removed
            entirely in future versions of Flower.
        
[2025-10-16 10:40:05,491][flwr][INFO] - Starting Flower simulation, config: num_rounds=1, no round_timeout
[2025-10-16 10:40:06,949][flwr][INFO] - Flower VCE: Ray initialized with resources: {'CPU': 20.0, 'object_store_memory': 8456347238.0, 'memory': 19731476890.0, 'node:__internal_head__': 1.0, 'node:10.100.14.161': 1.0}
[2025-10-16 10:40:06,949][flwr][INFO] - Optimize your simulation with Flower VCE: https://flower.ai/docs/framework/how-to-run-simulations.html
[2025-10-16 10:40:06,949][flwr][INFO] - No `client_resources` specified. Using minimal resources for clients.
[2025-10-16 10:40:06,949][flwr][INFO] - Flower VCE: Resources for each Virtual Client: {'num_cpus': 1, 'num_gpus': 0.0}
[2025-10-16 10:40:06,997][flwr][INFO] - Flower VCE: Creating VirtualClientEngineActorPool with 20 actors
[2025-10-16 10:40:06,997][flwr][INFO] - [INIT]
[2025-10-16 10:40:06,997][flwr][INFO] - Requesting initial parameters from one random client
[2025-10-16 10:40:08,442][flwr][INFO] - Received initial parameters from one random client
[2025-10-16 10:40:08,442][flwr][INFO] - Starting evaluation of initial global parameters
[2025-10-16 10:40:08,950][flwr][INFO] - initial parameters (loss, other metrics): 182.12883377075195, {'accuracy': 0.1026}
[2025-10-16 10:40:08,950][flwr][INFO] - 
[2025-10-16 10:40:08,950][flwr][INFO] - [ROUND 1]
[2025-10-16 10:40:08,951][flwr][INFO] - configure_fit: strategy sampled 10 clients (out of 100)
[2025-10-16 10:40:09,418][flwr][ERROR] - Traceback (most recent call last):
  File "/home/mamatha/anaconda3/lib/python3.13/site-packages/flwr/simulation/ray_transport/ray_client_proxy.py", line 95, in _submit_job
    out_mssg, updated_context = self.actor_pool.get_client_result(
                                ~~~~~~~~~~~~~~~~~~~~~~~~~~~~~~~~~^
        partition_id_str, timeout
        ^^^^^^^^^^^^^^^^^^^^^^^^^
    )
    ^
  File "/home/mamatha/anaconda3/lib/python3.13/site-packages/flwr/simulation/ray_transport/ray_actor.py", line 401, in get_client_result
    return self._fetch_future_result(cid)
           ~~~~~~~~~~~~~~~~~~~~~~~~~^^^^^
  File "/home/mamatha/anaconda3/lib/python3.13/site-packages/flwr/simulation/ray_transport/ray_actor.py", line 282, in _fetch_future_result
    res_cid, out_mssg, updated_context = ray.get(
                                         ~~~~~~~^
        future
        ^^^^^^
    )  # type: (str, Message, Context)
    ^
  File "/home/mamatha/anaconda3/lib/python3.13/site-packages/ray/_private/auto_init_hook.py", line 22, in auto_init_wrapper
    return fn(*args, **kwargs)
  File "/home/mamatha/anaconda3/lib/python3.13/site-packages/ray/_private/client_mode_hook.py", line 104, in wrapper
    return func(*args, **kwargs)
  File "/home/mamatha/anaconda3/lib/python3.13/site-packages/ray/_private/worker.py", line 2962, in get
    values, debugger_breakpoint = worker.get_objects(
                                  ~~~~~~~~~~~~~~~~~~^
        object_refs, timeout=timeout, _tensor_transport=_tensor_transport
        ^^^^^^^^^^^^^^^^^^^^^^^^^^^^^^^^^^^^^^^^^^^^^^^^^^^^^^^^^^^^^^^^^
    )
    ^
  File "/home/mamatha/anaconda3/lib/python3.13/site-packages/ray/_private/worker.py", line 1026, in get_objects
    raise value.as_instanceof_cause()
ray.exceptions.RayTaskError(ClientAppException): [36mray::ClientAppActor.run()[39m (pid=9379, ip=10.100.14.161, actor_id=ae22c91d04e149891201dd3e01000000, repr=<flwr.simulation.ray_transport.ray_actor.ClientAppActor object at 0x7f7834305010>)
  File "/home/mamatha/anaconda3/lib/python3.13/site-packages/flwr/client/client_app.py", line 144, in __call__
    return self._call(message, context)
           ~~~~~~~~~~^^^^^^^^^^^^^^^^^^
  File "/home/mamatha/anaconda3/lib/python3.13/site-packages/flwr/client/client_app.py", line 128, in ffn
    out_message = handle_legacy_message_from_msgtype(
        client_fn=client_fn, message=message, context=context
    )
  File "/home/mamatha/anaconda3/lib/python3.13/site-packages/flwr/client/message_handler/message_handler.py", line 128, in handle_legacy_message_from_msgtype
    fit_res = maybe_call_fit(
        client=client,
        fit_ins=recorddict_to_fitins(message.content, keep_input=True),
    )
  File "/home/mamatha/anaconda3/lib/python3.13/site-packages/flwr/client/client.py", line 224, in maybe_call_fit
    return client.fit(fit_ins)
           ~~~~~~~~~~^^^^^^^^^
  File "/home/mamatha/anaconda3/lib/python3.13/site-packages/flwr/client/numpy_client.py", line 227, in _fit
    results = self.numpy_client.fit(parameters, ins.config)  # type: ignore
  File "/home/mamatha/ME/Research/Hands-On/flower_tutorial/client.py", line 53, in fit
    optim = torch.optim.SGD(self.get_parameters(config['config_fit']), lr=lr, momentum=momentum)
                                                ~~~~~~^^^^^^^^^^^^^^
  File "/home/mamatha/anaconda3/lib/python3.13/site-packages/flwr/common/record/typeddict.py", line 52, in __getitem__
    return cast(dict[K, V], self.__dict__["_data"])[item]
           ~~~~~~~~~~~~~~~~~~~~~~~~~~~~~~~~~~~~~~~~^^^^^^
KeyError: 'config_fit'

The above exception was the direct cause of the following exception:

[36mray::ClientAppActor.run()[39m (pid=9379, ip=10.100.14.161, actor_id=ae22c91d04e149891201dd3e01000000, repr=<flwr.simulation.ray_transport.ray_actor.ClientAppActor object at 0x7f7834305010>)
  File "/home/mamatha/anaconda3/lib/python3.13/site-packages/flwr/simulation/ray_transport/ray_actor.py", line 64, in run
    raise ClientAppException(str(ex)) from ex
flwr.client.client_app.ClientAppException: 
Exception ClientAppException occurred. Message: 'config_fit'

[2025-10-16 10:40:09,419][flwr][ERROR] - [36mray::ClientAppActor.run()[39m (pid=9379, ip=10.100.14.161, actor_id=ae22c91d04e149891201dd3e01000000, repr=<flwr.simulation.ray_transport.ray_actor.ClientAppActor object at 0x7f7834305010>)
  File "/home/mamatha/anaconda3/lib/python3.13/site-packages/flwr/client/client_app.py", line 144, in __call__
    return self._call(message, context)
           ~~~~~~~~~~^^^^^^^^^^^^^^^^^^
  File "/home/mamatha/anaconda3/lib/python3.13/site-packages/flwr/client/client_app.py", line 128, in ffn
    out_message = handle_legacy_message_from_msgtype(
        client_fn=client_fn, message=message, context=context
    )
  File "/home/mamatha/anaconda3/lib/python3.13/site-packages/flwr/client/message_handler/message_handler.py", line 128, in handle_legacy_message_from_msgtype
    fit_res = maybe_call_fit(
        client=client,
        fit_ins=recorddict_to_fitins(message.content, keep_input=True),
    )
  File "/home/mamatha/anaconda3/lib/python3.13/site-packages/flwr/client/client.py", line 224, in maybe_call_fit
    return client.fit(fit_ins)
           ~~~~~~~~~~^^^^^^^^^
  File "/home/mamatha/anaconda3/lib/python3.13/site-packages/flwr/client/numpy_client.py", line 227, in _fit
    results = self.numpy_client.fit(parameters, ins.config)  # type: ignore
  File "/home/mamatha/ME/Research/Hands-On/flower_tutorial/client.py", line 53, in fit
    optim = torch.optim.SGD(self.get_parameters(config['config_fit']), lr=lr, momentum=momentum)
                                                ~~~~~~^^^^^^^^^^^^^^
  File "/home/mamatha/anaconda3/lib/python3.13/site-packages/flwr/common/record/typeddict.py", line 52, in __getitem__
    return cast(dict[K, V], self.__dict__["_data"])[item]
           ~~~~~~~~~~~~~~~~~~~~~~~~~~~~~~~~~~~~~~~~^^^^^^
KeyError: 'config_fit'

The above exception was the direct cause of the following exception:

[36mray::ClientAppActor.run()[39m (pid=9379, ip=10.100.14.161, actor_id=ae22c91d04e149891201dd3e01000000, repr=<flwr.simulation.ray_transport.ray_actor.ClientAppActor object at 0x7f7834305010>)
  File "/home/mamatha/anaconda3/lib/python3.13/site-packages/flwr/simulation/ray_transport/ray_actor.py", line 64, in run
    raise ClientAppException(str(ex)) from ex
flwr.client.client_app.ClientAppException: 
Exception ClientAppException occurred. Message: 'config_fit'
[2025-10-16 10:40:09,487][flwr][ERROR] - Traceback (most recent call last):
  File "/home/mamatha/anaconda3/lib/python3.13/site-packages/flwr/simulation/ray_transport/ray_client_proxy.py", line 95, in _submit_job
    out_mssg, updated_context = self.actor_pool.get_client_result(
                                ~~~~~~~~~~~~~~~~~~~~~~~~~~~~~~~~~^
        partition_id_str, timeout
        ^^^^^^^^^^^^^^^^^^^^^^^^^
    )
    ^
  File "/home/mamatha/anaconda3/lib/python3.13/site-packages/flwr/simulation/ray_transport/ray_actor.py", line 401, in get_client_result
    return self._fetch_future_result(cid)
           ~~~~~~~~~~~~~~~~~~~~~~~~~^^^^^
  File "/home/mamatha/anaconda3/lib/python3.13/site-packages/flwr/simulation/ray_transport/ray_actor.py", line 282, in _fetch_future_result
    res_cid, out_mssg, updated_context = ray.get(
                                         ~~~~~~~^
        future
        ^^^^^^
    )  # type: (str, Message, Context)
    ^
  File "/home/mamatha/anaconda3/lib/python3.13/site-packages/ray/_private/auto_init_hook.py", line 22, in auto_init_wrapper
    return fn(*args, **kwargs)
  File "/home/mamatha/anaconda3/lib/python3.13/site-packages/ray/_private/client_mode_hook.py", line 104, in wrapper
    return func(*args, **kwargs)
  File "/home/mamatha/anaconda3/lib/python3.13/site-packages/ray/_private/worker.py", line 2962, in get
    values, debugger_breakpoint = worker.get_objects(
                                  ~~~~~~~~~~~~~~~~~~^
        object_refs, timeout=timeout, _tensor_transport=_tensor_transport
        ^^^^^^^^^^^^^^^^^^^^^^^^^^^^^^^^^^^^^^^^^^^^^^^^^^^^^^^^^^^^^^^^^
    )
    ^
  File "/home/mamatha/anaconda3/lib/python3.13/site-packages/ray/_private/worker.py", line 1026, in get_objects
    raise value.as_instanceof_cause()
ray.exceptions.RayTaskError(ClientAppException): [36mray::ClientAppActor.run()[39m (pid=9379, ip=10.100.14.161, actor_id=ae22c91d04e149891201dd3e01000000, repr=<flwr.simulation.ray_transport.ray_actor.ClientAppActor object at 0x7f7834305010>)
  File "/home/mamatha/anaconda3/lib/python3.13/site-packages/flwr/client/client_app.py", line 144, in __call__
    return self._call(message, context)
           ~~~~~~~~~~^^^^^^^^^^^^^^^^^^
  File "/home/mamatha/anaconda3/lib/python3.13/site-packages/flwr/client/client_app.py", line 128, in ffn
    out_message = handle_legacy_message_from_msgtype(
        client_fn=client_fn, message=message, context=context
    )
  File "/home/mamatha/anaconda3/lib/python3.13/site-packages/flwr/client/message_handler/message_handler.py", line 128, in handle_legacy_message_from_msgtype
    fit_res = maybe_call_fit(
        client=client,
        fit_ins=recorddict_to_fitins(message.content, keep_input=True),
    )
  File "/home/mamatha/anaconda3/lib/python3.13/site-packages/flwr/client/client.py", line 224, in maybe_call_fit
    return client.fit(fit_ins)
           ~~~~~~~~~~^^^^^^^^^
  File "/home/mamatha/anaconda3/lib/python3.13/site-packages/flwr/client/numpy_client.py", line 227, in _fit
    results = self.numpy_client.fit(parameters, ins.config)  # type: ignore
  File "/home/mamatha/ME/Research/Hands-On/flower_tutorial/client.py", line 53, in fit
    optim = torch.optim.SGD(self.get_parameters(config['config_fit']), lr=lr, momentum=momentum)
                                                ~~~~~~^^^^^^^^^^^^^^
  File "/home/mamatha/anaconda3/lib/python3.13/site-packages/flwr/common/record/typeddict.py", line 52, in __getitem__
    return cast(dict[K, V], self.__dict__["_data"])[item]
           ~~~~~~~~~~~~~~~~~~~~~~~~~~~~~~~~~~~~~~~~^^^^^^
KeyError: 'config_fit'

The above exception was the direct cause of the following exception:

[36mray::ClientAppActor.run()[39m (pid=9379, ip=10.100.14.161, actor_id=ae22c91d04e149891201dd3e01000000, repr=<flwr.simulation.ray_transport.ray_actor.ClientAppActor object at 0x7f7834305010>)
  File "/home/mamatha/anaconda3/lib/python3.13/site-packages/flwr/simulation/ray_transport/ray_actor.py", line 64, in run
    raise ClientAppException(str(ex)) from ex
flwr.client.client_app.ClientAppException: 
Exception ClientAppException occurred. Message: 'config_fit'

[2025-10-16 10:40:09,487][flwr][ERROR] - [36mray::ClientAppActor.run()[39m (pid=9379, ip=10.100.14.161, actor_id=ae22c91d04e149891201dd3e01000000, repr=<flwr.simulation.ray_transport.ray_actor.ClientAppActor object at 0x7f7834305010>)
  File "/home/mamatha/anaconda3/lib/python3.13/site-packages/flwr/client/client_app.py", line 144, in __call__
    return self._call(message, context)
           ~~~~~~~~~~^^^^^^^^^^^^^^^^^^
  File "/home/mamatha/anaconda3/lib/python3.13/site-packages/flwr/client/client_app.py", line 128, in ffn
    out_message = handle_legacy_message_from_msgtype(
        client_fn=client_fn, message=message, context=context
    )
  File "/home/mamatha/anaconda3/lib/python3.13/site-packages/flwr/client/message_handler/message_handler.py", line 128, in handle_legacy_message_from_msgtype
    fit_res = maybe_call_fit(
        client=client,
        fit_ins=recorddict_to_fitins(message.content, keep_input=True),
    )
  File "/home/mamatha/anaconda3/lib/python3.13/site-packages/flwr/client/client.py", line 224, in maybe_call_fit
    return client.fit(fit_ins)
           ~~~~~~~~~~^^^^^^^^^
  File "/home/mamatha/anaconda3/lib/python3.13/site-packages/flwr/client/numpy_client.py", line 227, in _fit
    results = self.numpy_client.fit(parameters, ins.config)  # type: ignore
  File "/home/mamatha/ME/Research/Hands-On/flower_tutorial/client.py", line 53, in fit
    optim = torch.optim.SGD(self.get_parameters(config['config_fit']), lr=lr, momentum=momentum)
                                                ~~~~~~^^^^^^^^^^^^^^
  File "/home/mamatha/anaconda3/lib/python3.13/site-packages/flwr/common/record/typeddict.py", line 52, in __getitem__
    return cast(dict[K, V], self.__dict__["_data"])[item]
           ~~~~~~~~~~~~~~~~~~~~~~~~~~~~~~~~~~~~~~~~^^^^^^
KeyError: 'config_fit'

The above exception was the direct cause of the following exception:

[36mray::ClientAppActor.run()[39m (pid=9379, ip=10.100.14.161, actor_id=ae22c91d04e149891201dd3e01000000, repr=<flwr.simulation.ray_transport.ray_actor.ClientAppActor object at 0x7f7834305010>)
  File "/home/mamatha/anaconda3/lib/python3.13/site-packages/flwr/simulation/ray_transport/ray_actor.py", line 64, in run
    raise ClientAppException(str(ex)) from ex
flwr.client.client_app.ClientAppException: 
Exception ClientAppException occurred. Message: 'config_fit'
[2025-10-16 10:40:10,458][flwr][ERROR] - Traceback (most recent call last):
  File "/home/mamatha/anaconda3/lib/python3.13/site-packages/flwr/simulation/ray_transport/ray_client_proxy.py", line 95, in _submit_job
    out_mssg, updated_context = self.actor_pool.get_client_result(
                                ~~~~~~~~~~~~~~~~~~~~~~~~~~~~~~~~~^
        partition_id_str, timeout
        ^^^^^^^^^^^^^^^^^^^^^^^^^
    )
    ^
  File "/home/mamatha/anaconda3/lib/python3.13/site-packages/flwr/simulation/ray_transport/ray_actor.py", line 401, in get_client_result
    return self._fetch_future_result(cid)
           ~~~~~~~~~~~~~~~~~~~~~~~~~^^^^^
  File "/home/mamatha/anaconda3/lib/python3.13/site-packages/flwr/simulation/ray_transport/ray_actor.py", line 282, in _fetch_future_result
    res_cid, out_mssg, updated_context = ray.get(
                                         ~~~~~~~^
        future
        ^^^^^^
    )  # type: (str, Message, Context)
    ^
  File "/home/mamatha/anaconda3/lib/python3.13/site-packages/ray/_private/auto_init_hook.py", line 22, in auto_init_wrapper
    return fn(*args, **kwargs)
  File "/home/mamatha/anaconda3/lib/python3.13/site-packages/ray/_private/client_mode_hook.py", line 104, in wrapper
    return func(*args, **kwargs)
  File "/home/mamatha/anaconda3/lib/python3.13/site-packages/ray/_private/worker.py", line 2962, in get
    values, debugger_breakpoint = worker.get_objects(
                                  ~~~~~~~~~~~~~~~~~~^
        object_refs, timeout=timeout, _tensor_transport=_tensor_transport
        ^^^^^^^^^^^^^^^^^^^^^^^^^^^^^^^^^^^^^^^^^^^^^^^^^^^^^^^^^^^^^^^^^
    )
    ^
  File "/home/mamatha/anaconda3/lib/python3.13/site-packages/ray/_private/worker.py", line 1026, in get_objects
    raise value.as_instanceof_cause()
ray.exceptions.RayTaskError(ClientAppException): [36mray::ClientAppActor.run()[39m (pid=9363, ip=10.100.14.161, actor_id=08bef2ac58c04a7e3adb53b601000000, repr=<flwr.simulation.ray_transport.ray_actor.ClientAppActor object at 0x7f275403d010>)
  File "/home/mamatha/anaconda3/lib/python3.13/site-packages/flwr/client/client_app.py", line 144, in __call__
    return self._call(message, context)
           ~~~~~~~~~~^^^^^^^^^^^^^^^^^^
  File "/home/mamatha/anaconda3/lib/python3.13/site-packages/flwr/client/client_app.py", line 128, in ffn
    out_message = handle_legacy_message_from_msgtype(
        client_fn=client_fn, message=message, context=context
    )
  File "/home/mamatha/anaconda3/lib/python3.13/site-packages/flwr/client/message_handler/message_handler.py", line 128, in handle_legacy_message_from_msgtype
    fit_res = maybe_call_fit(
        client=client,
        fit_ins=recorddict_to_fitins(message.content, keep_input=True),
    )
  File "/home/mamatha/anaconda3/lib/python3.13/site-packages/flwr/client/client.py", line 224, in maybe_call_fit
    return client.fit(fit_ins)
           ~~~~~~~~~~^^^^^^^^^
  File "/home/mamatha/anaconda3/lib/python3.13/site-packages/flwr/client/numpy_client.py", line 227, in _fit
    results = self.numpy_client.fit(parameters, ins.config)  # type: ignore
  File "/home/mamatha/ME/Research/Hands-On/flower_tutorial/client.py", line 53, in fit
    optim = torch.optim.SGD(self.get_parameters(config['config_fit']), lr=lr, momentum=momentum)
                                                ~~~~~~^^^^^^^^^^^^^^
  File "/home/mamatha/anaconda3/lib/python3.13/site-packages/flwr/common/record/typeddict.py", line 52, in __getitem__
    return cast(dict[K, V], self.__dict__["_data"])[item]
           ~~~~~~~~~~~~~~~~~~~~~~~~~~~~~~~~~~~~~~~~^^^^^^
KeyError: 'config_fit'

The above exception was the direct cause of the following exception:

[36mray::ClientAppActor.run()[39m (pid=9363, ip=10.100.14.161, actor_id=08bef2ac58c04a7e3adb53b601000000, repr=<flwr.simulation.ray_transport.ray_actor.ClientAppActor object at 0x7f275403d010>)
  File "/home/mamatha/anaconda3/lib/python3.13/site-packages/flwr/simulation/ray_transport/ray_actor.py", line 64, in run
    raise ClientAppException(str(ex)) from ex
flwr.client.client_app.ClientAppException: 
Exception ClientAppException occurred. Message: 'config_fit'

[2025-10-16 10:40:10,458][flwr][ERROR] - [36mray::ClientAppActor.run()[39m (pid=9363, ip=10.100.14.161, actor_id=08bef2ac58c04a7e3adb53b601000000, repr=<flwr.simulation.ray_transport.ray_actor.ClientAppActor object at 0x7f275403d010>)
  File "/home/mamatha/anaconda3/lib/python3.13/site-packages/flwr/client/client_app.py", line 144, in __call__
    return self._call(message, context)
           ~~~~~~~~~~^^^^^^^^^^^^^^^^^^
  File "/home/mamatha/anaconda3/lib/python3.13/site-packages/flwr/client/client_app.py", line 128, in ffn
    out_message = handle_legacy_message_from_msgtype(
        client_fn=client_fn, message=message, context=context
    )
  File "/home/mamatha/anaconda3/lib/python3.13/site-packages/flwr/client/message_handler/message_handler.py", line 128, in handle_legacy_message_from_msgtype
    fit_res = maybe_call_fit(
        client=client,
        fit_ins=recorddict_to_fitins(message.content, keep_input=True),
    )
  File "/home/mamatha/anaconda3/lib/python3.13/site-packages/flwr/client/client.py", line 224, in maybe_call_fit
    return client.fit(fit_ins)
           ~~~~~~~~~~^^^^^^^^^
  File "/home/mamatha/anaconda3/lib/python3.13/site-packages/flwr/client/numpy_client.py", line 227, in _fit
    results = self.numpy_client.fit(parameters, ins.config)  # type: ignore
  File "/home/mamatha/ME/Research/Hands-On/flower_tutorial/client.py", line 53, in fit
    optim = torch.optim.SGD(self.get_parameters(config['config_fit']), lr=lr, momentum=momentum)
                                                ~~~~~~^^^^^^^^^^^^^^
  File "/home/mamatha/anaconda3/lib/python3.13/site-packages/flwr/common/record/typeddict.py", line 52, in __getitem__
    return cast(dict[K, V], self.__dict__["_data"])[item]
           ~~~~~~~~~~~~~~~~~~~~~~~~~~~~~~~~~~~~~~~~^^^^^^
KeyError: 'config_fit'

The above exception was the direct cause of the following exception:

[36mray::ClientAppActor.run()[39m (pid=9363, ip=10.100.14.161, actor_id=08bef2ac58c04a7e3adb53b601000000, repr=<flwr.simulation.ray_transport.ray_actor.ClientAppActor object at 0x7f275403d010>)
  File "/home/mamatha/anaconda3/lib/python3.13/site-packages/flwr/simulation/ray_transport/ray_actor.py", line 64, in run
    raise ClientAppException(str(ex)) from ex
flwr.client.client_app.ClientAppException: 
Exception ClientAppException occurred. Message: 'config_fit'
[2025-10-16 10:40:10,544][flwr][ERROR] - Traceback (most recent call last):
  File "/home/mamatha/anaconda3/lib/python3.13/site-packages/flwr/simulation/ray_transport/ray_client_proxy.py", line 95, in _submit_job
    out_mssg, updated_context = self.actor_pool.get_client_result(
                                ~~~~~~~~~~~~~~~~~~~~~~~~~~~~~~~~~^
        partition_id_str, timeout
        ^^^^^^^^^^^^^^^^^^^^^^^^^
    )
    ^
  File "/home/mamatha/anaconda3/lib/python3.13/site-packages/flwr/simulation/ray_transport/ray_actor.py", line 401, in get_client_result
    return self._fetch_future_result(cid)
           ~~~~~~~~~~~~~~~~~~~~~~~~~^^^^^
  File "/home/mamatha/anaconda3/lib/python3.13/site-packages/flwr/simulation/ray_transport/ray_actor.py", line 282, in _fetch_future_result
    res_cid, out_mssg, updated_context = ray.get(
                                         ~~~~~~~^
        future
        ^^^^^^
    )  # type: (str, Message, Context)
    ^
  File "/home/mamatha/anaconda3/lib/python3.13/site-packages/ray/_private/auto_init_hook.py", line 22, in auto_init_wrapper
    return fn(*args, **kwargs)
  File "/home/mamatha/anaconda3/lib/python3.13/site-packages/ray/_private/client_mode_hook.py", line 104, in wrapper
    return func(*args, **kwargs)
  File "/home/mamatha/anaconda3/lib/python3.13/site-packages/ray/_private/worker.py", line 2962, in get
    values, debugger_breakpoint = worker.get_objects(
                                  ~~~~~~~~~~~~~~~~~~^
        object_refs, timeout=timeout, _tensor_transport=_tensor_transport
        ^^^^^^^^^^^^^^^^^^^^^^^^^^^^^^^^^^^^^^^^^^^^^^^^^^^^^^^^^^^^^^^^^
    )
    ^
  File "/home/mamatha/anaconda3/lib/python3.13/site-packages/ray/_private/worker.py", line 1026, in get_objects
    raise value.as_instanceof_cause()
ray.exceptions.RayTaskError(ClientAppException): [36mray::ClientAppActor.run()[39m (pid=9380, ip=10.100.14.161, actor_id=e1be491ca222e5f7cb2edbbf01000000, repr=<flwr.simulation.ray_transport.ray_actor.ClientAppActor object at 0x7f5fe03d9010>)
  File "/home/mamatha/anaconda3/lib/python3.13/site-packages/flwr/client/client_app.py", line 144, in __call__
    return self._call(message, context)
           ~~~~~~~~~~^^^^^^^^^^^^^^^^^^
  File "/home/mamatha/anaconda3/lib/python3.13/site-packages/flwr/client/client_app.py", line 128, in ffn
    out_message = handle_legacy_message_from_msgtype(
        client_fn=client_fn, message=message, context=context
    )
  File "/home/mamatha/anaconda3/lib/python3.13/site-packages/flwr/client/message_handler/message_handler.py", line 128, in handle_legacy_message_from_msgtype
    fit_res = maybe_call_fit(
        client=client,
        fit_ins=recorddict_to_fitins(message.content, keep_input=True),
    )
  File "/home/mamatha/anaconda3/lib/python3.13/site-packages/flwr/client/client.py", line 224, in maybe_call_fit
    return client.fit(fit_ins)
           ~~~~~~~~~~^^^^^^^^^
  File "/home/mamatha/anaconda3/lib/python3.13/site-packages/flwr/client/numpy_client.py", line 227, in _fit
    results = self.numpy_client.fit(parameters, ins.config)  # type: ignore
  File "/home/mamatha/ME/Research/Hands-On/flower_tutorial/client.py", line 53, in fit
    optim = torch.optim.SGD(self.get_parameters(config['config_fit']), lr=lr, momentum=momentum)
                                                ~~~~~~^^^^^^^^^^^^^^
  File "/home/mamatha/anaconda3/lib/python3.13/site-packages/flwr/common/record/typeddict.py", line 52, in __getitem__
    return cast(dict[K, V], self.__dict__["_data"])[item]
           ~~~~~~~~~~~~~~~~~~~~~~~~~~~~~~~~~~~~~~~~^^^^^^
KeyError: 'config_fit'

The above exception was the direct cause of the following exception:

[36mray::ClientAppActor.run()[39m (pid=9380, ip=10.100.14.161, actor_id=e1be491ca222e5f7cb2edbbf01000000, repr=<flwr.simulation.ray_transport.ray_actor.ClientAppActor object at 0x7f5fe03d9010>)
  File "/home/mamatha/anaconda3/lib/python3.13/site-packages/flwr/simulation/ray_transport/ray_actor.py", line 64, in run
    raise ClientAppException(str(ex)) from ex
flwr.client.client_app.ClientAppException: 
Exception ClientAppException occurred. Message: 'config_fit'

[2025-10-16 10:40:10,544][flwr][ERROR] - [36mray::ClientAppActor.run()[39m (pid=9380, ip=10.100.14.161, actor_id=e1be491ca222e5f7cb2edbbf01000000, repr=<flwr.simulation.ray_transport.ray_actor.ClientAppActor object at 0x7f5fe03d9010>)
  File "/home/mamatha/anaconda3/lib/python3.13/site-packages/flwr/client/client_app.py", line 144, in __call__
    return self._call(message, context)
           ~~~~~~~~~~^^^^^^^^^^^^^^^^^^
  File "/home/mamatha/anaconda3/lib/python3.13/site-packages/flwr/client/client_app.py", line 128, in ffn
    out_message = handle_legacy_message_from_msgtype(
        client_fn=client_fn, message=message, context=context
    )
  File "/home/mamatha/anaconda3/lib/python3.13/site-packages/flwr/client/message_handler/message_handler.py", line 128, in handle_legacy_message_from_msgtype
    fit_res = maybe_call_fit(
        client=client,
        fit_ins=recorddict_to_fitins(message.content, keep_input=True),
    )
  File "/home/mamatha/anaconda3/lib/python3.13/site-packages/flwr/client/client.py", line 224, in maybe_call_fit
    return client.fit(fit_ins)
           ~~~~~~~~~~^^^^^^^^^
  File "/home/mamatha/anaconda3/lib/python3.13/site-packages/flwr/client/numpy_client.py", line 227, in _fit
    results = self.numpy_client.fit(parameters, ins.config)  # type: ignore
  File "/home/mamatha/ME/Research/Hands-On/flower_tutorial/client.py", line 53, in fit
    optim = torch.optim.SGD(self.get_parameters(config['config_fit']), lr=lr, momentum=momentum)
                                                ~~~~~~^^^^^^^^^^^^^^
  File "/home/mamatha/anaconda3/lib/python3.13/site-packages/flwr/common/record/typeddict.py", line 52, in __getitem__
    return cast(dict[K, V], self.__dict__["_data"])[item]
           ~~~~~~~~~~~~~~~~~~~~~~~~~~~~~~~~~~~~~~~~^^^^^^
KeyError: 'config_fit'

The above exception was the direct cause of the following exception:

[36mray::ClientAppActor.run()[39m (pid=9380, ip=10.100.14.161, actor_id=e1be491ca222e5f7cb2edbbf01000000, repr=<flwr.simulation.ray_transport.ray_actor.ClientAppActor object at 0x7f5fe03d9010>)
  File "/home/mamatha/anaconda3/lib/python3.13/site-packages/flwr/simulation/ray_transport/ray_actor.py", line 64, in run
    raise ClientAppException(str(ex)) from ex
flwr.client.client_app.ClientAppException: 
Exception ClientAppException occurred. Message: 'config_fit'
[2025-10-16 10:40:10,594][flwr][ERROR] - Traceback (most recent call last):
  File "/home/mamatha/anaconda3/lib/python3.13/site-packages/flwr/simulation/ray_transport/ray_client_proxy.py", line 95, in _submit_job
    out_mssg, updated_context = self.actor_pool.get_client_result(
                                ~~~~~~~~~~~~~~~~~~~~~~~~~~~~~~~~~^
        partition_id_str, timeout
        ^^^^^^^^^^^^^^^^^^^^^^^^^
    )
    ^
  File "/home/mamatha/anaconda3/lib/python3.13/site-packages/flwr/simulation/ray_transport/ray_actor.py", line 401, in get_client_result
    return self._fetch_future_result(cid)
           ~~~~~~~~~~~~~~~~~~~~~~~~~^^^^^
  File "/home/mamatha/anaconda3/lib/python3.13/site-packages/flwr/simulation/ray_transport/ray_actor.py", line 282, in _fetch_future_result
    res_cid, out_mssg, updated_context = ray.get(
                                         ~~~~~~~^
        future
        ^^^^^^
    )  # type: (str, Message, Context)
    ^
  File "/home/mamatha/anaconda3/lib/python3.13/site-packages/ray/_private/auto_init_hook.py", line 22, in auto_init_wrapper
    return fn(*args, **kwargs)
  File "/home/mamatha/anaconda3/lib/python3.13/site-packages/ray/_private/client_mode_hook.py", line 104, in wrapper
    return func(*args, **kwargs)
  File "/home/mamatha/anaconda3/lib/python3.13/site-packages/ray/_private/worker.py", line 2962, in get
    values, debugger_breakpoint = worker.get_objects(
                                  ~~~~~~~~~~~~~~~~~~^
        object_refs, timeout=timeout, _tensor_transport=_tensor_transport
        ^^^^^^^^^^^^^^^^^^^^^^^^^^^^^^^^^^^^^^^^^^^^^^^^^^^^^^^^^^^^^^^^^
    )
    ^
  File "/home/mamatha/anaconda3/lib/python3.13/site-packages/ray/_private/worker.py", line 1026, in get_objects
    raise value.as_instanceof_cause()
ray.exceptions.RayTaskError(ClientAppException): [36mray::ClientAppActor.run()[39m (pid=9370, ip=10.100.14.161, actor_id=6e21a9799626846df60b361b01000000, repr=<flwr.simulation.ray_transport.ray_actor.ClientAppActor object at 0x7ff1fc0a1010>)
  File "/home/mamatha/anaconda3/lib/python3.13/site-packages/flwr/client/client_app.py", line 144, in __call__
    return self._call(message, context)
           ~~~~~~~~~~^^^^^^^^^^^^^^^^^^
  File "/home/mamatha/anaconda3/lib/python3.13/site-packages/flwr/client/client_app.py", line 128, in ffn
    out_message = handle_legacy_message_from_msgtype(
        client_fn=client_fn, message=message, context=context
    )
  File "/home/mamatha/anaconda3/lib/python3.13/site-packages/flwr/client/message_handler/message_handler.py", line 128, in handle_legacy_message_from_msgtype
    fit_res = maybe_call_fit(
        client=client,
        fit_ins=recorddict_to_fitins(message.content, keep_input=True),
    )
  File "/home/mamatha/anaconda3/lib/python3.13/site-packages/flwr/client/client.py", line 224, in maybe_call_fit
    return client.fit(fit_ins)
           ~~~~~~~~~~^^^^^^^^^
  File "/home/mamatha/anaconda3/lib/python3.13/site-packages/flwr/client/numpy_client.py", line 227, in _fit
    results = self.numpy_client.fit(parameters, ins.config)  # type: ignore
  File "/home/mamatha/ME/Research/Hands-On/flower_tutorial/client.py", line 53, in fit
    optim = torch.optim.SGD(self.get_parameters(config['config_fit']), lr=lr, momentum=momentum)
                                                ~~~~~~^^^^^^^^^^^^^^
  File "/home/mamatha/anaconda3/lib/python3.13/site-packages/flwr/common/record/typeddict.py", line 52, in __getitem__
    return cast(dict[K, V], self.__dict__["_data"])[item]
           ~~~~~~~~~~~~~~~~~~~~~~~~~~~~~~~~~~~~~~~~^^^^^^
KeyError: 'config_fit'

The above exception was the direct cause of the following exception:

[36mray::ClientAppActor.run()[39m (pid=9370, ip=10.100.14.161, actor_id=6e21a9799626846df60b361b01000000, repr=<flwr.simulation.ray_transport.ray_actor.ClientAppActor object at 0x7ff1fc0a1010>)
  File "/home/mamatha/anaconda3/lib/python3.13/site-packages/flwr/simulation/ray_transport/ray_actor.py", line 64, in run
    raise ClientAppException(str(ex)) from ex
flwr.client.client_app.ClientAppException: 
Exception ClientAppException occurred. Message: 'config_fit'

[2025-10-16 10:40:10,595][flwr][ERROR] - [36mray::ClientAppActor.run()[39m (pid=9370, ip=10.100.14.161, actor_id=6e21a9799626846df60b361b01000000, repr=<flwr.simulation.ray_transport.ray_actor.ClientAppActor object at 0x7ff1fc0a1010>)
  File "/home/mamatha/anaconda3/lib/python3.13/site-packages/flwr/client/client_app.py", line 144, in __call__
    return self._call(message, context)
           ~~~~~~~~~~^^^^^^^^^^^^^^^^^^
  File "/home/mamatha/anaconda3/lib/python3.13/site-packages/flwr/client/client_app.py", line 128, in ffn
    out_message = handle_legacy_message_from_msgtype(
        client_fn=client_fn, message=message, context=context
    )
  File "/home/mamatha/anaconda3/lib/python3.13/site-packages/flwr/client/message_handler/message_handler.py", line 128, in handle_legacy_message_from_msgtype
    fit_res = maybe_call_fit(
        client=client,
        fit_ins=recorddict_to_fitins(message.content, keep_input=True),
    )
  File "/home/mamatha/anaconda3/lib/python3.13/site-packages/flwr/client/client.py", line 224, in maybe_call_fit
    return client.fit(fit_ins)
           ~~~~~~~~~~^^^^^^^^^
  File "/home/mamatha/anaconda3/lib/python3.13/site-packages/flwr/client/numpy_client.py", line 227, in _fit
    results = self.numpy_client.fit(parameters, ins.config)  # type: ignore
  File "/home/mamatha/ME/Research/Hands-On/flower_tutorial/client.py", line 53, in fit
    optim = torch.optim.SGD(self.get_parameters(config['config_fit']), lr=lr, momentum=momentum)
                                                ~~~~~~^^^^^^^^^^^^^^
  File "/home/mamatha/anaconda3/lib/python3.13/site-packages/flwr/common/record/typeddict.py", line 52, in __getitem__
    return cast(dict[K, V], self.__dict__["_data"])[item]
           ~~~~~~~~~~~~~~~~~~~~~~~~~~~~~~~~~~~~~~~~^^^^^^
KeyError: 'config_fit'

The above exception was the direct cause of the following exception:

[36mray::ClientAppActor.run()[39m (pid=9370, ip=10.100.14.161, actor_id=6e21a9799626846df60b361b01000000, repr=<flwr.simulation.ray_transport.ray_actor.ClientAppActor object at 0x7ff1fc0a1010>)
  File "/home/mamatha/anaconda3/lib/python3.13/site-packages/flwr/simulation/ray_transport/ray_actor.py", line 64, in run
    raise ClientAppException(str(ex)) from ex
flwr.client.client_app.ClientAppException: 
Exception ClientAppException occurred. Message: 'config_fit'
[2025-10-16 10:40:10,635][flwr][ERROR] - Traceback (most recent call last):
  File "/home/mamatha/anaconda3/lib/python3.13/site-packages/flwr/simulation/ray_transport/ray_client_proxy.py", line 95, in _submit_job
    out_mssg, updated_context = self.actor_pool.get_client_result(
                                ~~~~~~~~~~~~~~~~~~~~~~~~~~~~~~~~~^
        partition_id_str, timeout
        ^^^^^^^^^^^^^^^^^^^^^^^^^
    )
    ^
  File "/home/mamatha/anaconda3/lib/python3.13/site-packages/flwr/simulation/ray_transport/ray_actor.py", line 401, in get_client_result
    return self._fetch_future_result(cid)
           ~~~~~~~~~~~~~~~~~~~~~~~~~^^^^^
  File "/home/mamatha/anaconda3/lib/python3.13/site-packages/flwr/simulation/ray_transport/ray_actor.py", line 282, in _fetch_future_result
    res_cid, out_mssg, updated_context = ray.get(
                                         ~~~~~~~^
        future
        ^^^^^^
    )  # type: (str, Message, Context)
    ^
  File "/home/mamatha/anaconda3/lib/python3.13/site-packages/ray/_private/auto_init_hook.py", line 22, in auto_init_wrapper
    return fn(*args, **kwargs)
  File "/home/mamatha/anaconda3/lib/python3.13/site-packages/ray/_private/client_mode_hook.py", line 104, in wrapper
    return func(*args, **kwargs)
  File "/home/mamatha/anaconda3/lib/python3.13/site-packages/ray/_private/worker.py", line 2962, in get
    values, debugger_breakpoint = worker.get_objects(
                                  ~~~~~~~~~~~~~~~~~~^
        object_refs, timeout=timeout, _tensor_transport=_tensor_transport
        ^^^^^^^^^^^^^^^^^^^^^^^^^^^^^^^^^^^^^^^^^^^^^^^^^^^^^^^^^^^^^^^^^
    )
    ^
  File "/home/mamatha/anaconda3/lib/python3.13/site-packages/ray/_private/worker.py", line 1026, in get_objects
    raise value.as_instanceof_cause()
ray.exceptions.RayTaskError(ClientAppException): [36mray::ClientAppActor.run()[39m (pid=9372, ip=10.100.14.161, actor_id=0d602713c63d476b6c92e8dc01000000, repr=<flwr.simulation.ray_transport.ray_actor.ClientAppActor object at 0x7f8ebc0e1010>)
  File "/home/mamatha/anaconda3/lib/python3.13/site-packages/flwr/client/client_app.py", line 144, in __call__
    return self._call(message, context)
           ~~~~~~~~~~^^^^^^^^^^^^^^^^^^
  File "/home/mamatha/anaconda3/lib/python3.13/site-packages/flwr/client/client_app.py", line 128, in ffn
    out_message = handle_legacy_message_from_msgtype(
        client_fn=client_fn, message=message, context=context
    )
  File "/home/mamatha/anaconda3/lib/python3.13/site-packages/flwr/client/message_handler/message_handler.py", line 128, in handle_legacy_message_from_msgtype
    fit_res = maybe_call_fit(
        client=client,
        fit_ins=recorddict_to_fitins(message.content, keep_input=True),
    )
  File "/home/mamatha/anaconda3/lib/python3.13/site-packages/flwr/client/client.py", line 224, in maybe_call_fit
    return client.fit(fit_ins)
           ~~~~~~~~~~^^^^^^^^^
  File "/home/mamatha/anaconda3/lib/python3.13/site-packages/flwr/client/numpy_client.py", line 227, in _fit
    results = self.numpy_client.fit(parameters, ins.config)  # type: ignore
  File "/home/mamatha/ME/Research/Hands-On/flower_tutorial/client.py", line 53, in fit
    optim = torch.optim.SGD(self.get_parameters(config['config_fit']), lr=lr, momentum=momentum)
                                                ~~~~~~^^^^^^^^^^^^^^
  File "/home/mamatha/anaconda3/lib/python3.13/site-packages/flwr/common/record/typeddict.py", line 52, in __getitem__
    return cast(dict[K, V], self.__dict__["_data"])[item]
           ~~~~~~~~~~~~~~~~~~~~~~~~~~~~~~~~~~~~~~~~^^^^^^
KeyError: 'config_fit'

The above exception was the direct cause of the following exception:

[36mray::ClientAppActor.run()[39m (pid=9372, ip=10.100.14.161, actor_id=0d602713c63d476b6c92e8dc01000000, repr=<flwr.simulation.ray_transport.ray_actor.ClientAppActor object at 0x7f8ebc0e1010>)
  File "/home/mamatha/anaconda3/lib/python3.13/site-packages/flwr/simulation/ray_transport/ray_actor.py", line 64, in run
    raise ClientAppException(str(ex)) from ex
flwr.client.client_app.ClientAppException: 
Exception ClientAppException occurred. Message: 'config_fit'

[2025-10-16 10:40:10,635][flwr][ERROR] - [36mray::ClientAppActor.run()[39m (pid=9372, ip=10.100.14.161, actor_id=0d602713c63d476b6c92e8dc01000000, repr=<flwr.simulation.ray_transport.ray_actor.ClientAppActor object at 0x7f8ebc0e1010>)
  File "/home/mamatha/anaconda3/lib/python3.13/site-packages/flwr/client/client_app.py", line 144, in __call__
    return self._call(message, context)
           ~~~~~~~~~~^^^^^^^^^^^^^^^^^^
  File "/home/mamatha/anaconda3/lib/python3.13/site-packages/flwr/client/client_app.py", line 128, in ffn
    out_message = handle_legacy_message_from_msgtype(
        client_fn=client_fn, message=message, context=context
    )
  File "/home/mamatha/anaconda3/lib/python3.13/site-packages/flwr/client/message_handler/message_handler.py", line 128, in handle_legacy_message_from_msgtype
    fit_res = maybe_call_fit(
        client=client,
        fit_ins=recorddict_to_fitins(message.content, keep_input=True),
    )
  File "/home/mamatha/anaconda3/lib/python3.13/site-packages/flwr/client/client.py", line 224, in maybe_call_fit
    return client.fit(fit_ins)
           ~~~~~~~~~~^^^^^^^^^
  File "/home/mamatha/anaconda3/lib/python3.13/site-packages/flwr/client/numpy_client.py", line 227, in _fit
    results = self.numpy_client.fit(parameters, ins.config)  # type: ignore
  File "/home/mamatha/ME/Research/Hands-On/flower_tutorial/client.py", line 53, in fit
    optim = torch.optim.SGD(self.get_parameters(config['config_fit']), lr=lr, momentum=momentum)
                                                ~~~~~~^^^^^^^^^^^^^^
  File "/home/mamatha/anaconda3/lib/python3.13/site-packages/flwr/common/record/typeddict.py", line 52, in __getitem__
    return cast(dict[K, V], self.__dict__["_data"])[item]
           ~~~~~~~~~~~~~~~~~~~~~~~~~~~~~~~~~~~~~~~~^^^^^^
KeyError: 'config_fit'

The above exception was the direct cause of the following exception:

[36mray::ClientAppActor.run()[39m (pid=9372, ip=10.100.14.161, actor_id=0d602713c63d476b6c92e8dc01000000, repr=<flwr.simulation.ray_transport.ray_actor.ClientAppActor object at 0x7f8ebc0e1010>)
  File "/home/mamatha/anaconda3/lib/python3.13/site-packages/flwr/simulation/ray_transport/ray_actor.py", line 64, in run
    raise ClientAppException(str(ex)) from ex
flwr.client.client_app.ClientAppException: 
Exception ClientAppException occurred. Message: 'config_fit'
[2025-10-16 10:40:10,685][flwr][ERROR] - Traceback (most recent call last):
  File "/home/mamatha/anaconda3/lib/python3.13/site-packages/flwr/simulation/ray_transport/ray_client_proxy.py", line 95, in _submit_job
    out_mssg, updated_context = self.actor_pool.get_client_result(
                                ~~~~~~~~~~~~~~~~~~~~~~~~~~~~~~~~~^
        partition_id_str, timeout
        ^^^^^^^^^^^^^^^^^^^^^^^^^
    )
    ^
  File "/home/mamatha/anaconda3/lib/python3.13/site-packages/flwr/simulation/ray_transport/ray_actor.py", line 401, in get_client_result
    return self._fetch_future_result(cid)
           ~~~~~~~~~~~~~~~~~~~~~~~~~^^^^^
  File "/home/mamatha/anaconda3/lib/python3.13/site-packages/flwr/simulation/ray_transport/ray_actor.py", line 282, in _fetch_future_result
    res_cid, out_mssg, updated_context = ray.get(
                                         ~~~~~~~^
        future
        ^^^^^^
    )  # type: (str, Message, Context)
    ^
  File "/home/mamatha/anaconda3/lib/python3.13/site-packages/ray/_private/auto_init_hook.py", line 22, in auto_init_wrapper
    return fn(*args, **kwargs)
  File "/home/mamatha/anaconda3/lib/python3.13/site-packages/ray/_private/client_mode_hook.py", line 104, in wrapper
    return func(*args, **kwargs)
  File "/home/mamatha/anaconda3/lib/python3.13/site-packages/ray/_private/worker.py", line 2962, in get
    values, debugger_breakpoint = worker.get_objects(
                                  ~~~~~~~~~~~~~~~~~~^
        object_refs, timeout=timeout, _tensor_transport=_tensor_transport
        ^^^^^^^^^^^^^^^^^^^^^^^^^^^^^^^^^^^^^^^^^^^^^^^^^^^^^^^^^^^^^^^^^
    )
    ^
  File "/home/mamatha/anaconda3/lib/python3.13/site-packages/ray/_private/worker.py", line 1026, in get_objects
    raise value.as_instanceof_cause()
ray.exceptions.RayTaskError(ClientAppException): [36mray::ClientAppActor.run()[39m (pid=9377, ip=10.100.14.161, actor_id=2ed9d15c180df5bc1221911e01000000, repr=<flwr.simulation.ray_transport.ray_actor.ClientAppActor object at 0x7fb7e4379010>)
  File "/home/mamatha/anaconda3/lib/python3.13/site-packages/flwr/client/client_app.py", line 144, in __call__
    return self._call(message, context)
           ~~~~~~~~~~^^^^^^^^^^^^^^^^^^
  File "/home/mamatha/anaconda3/lib/python3.13/site-packages/flwr/client/client_app.py", line 128, in ffn
    out_message = handle_legacy_message_from_msgtype(
        client_fn=client_fn, message=message, context=context
    )
  File "/home/mamatha/anaconda3/lib/python3.13/site-packages/flwr/client/message_handler/message_handler.py", line 128, in handle_legacy_message_from_msgtype
    fit_res = maybe_call_fit(
        client=client,
        fit_ins=recorddict_to_fitins(message.content, keep_input=True),
    )
  File "/home/mamatha/anaconda3/lib/python3.13/site-packages/flwr/client/client.py", line 224, in maybe_call_fit
    return client.fit(fit_ins)
           ~~~~~~~~~~^^^^^^^^^
  File "/home/mamatha/anaconda3/lib/python3.13/site-packages/flwr/client/numpy_client.py", line 227, in _fit
    results = self.numpy_client.fit(parameters, ins.config)  # type: ignore
  File "/home/mamatha/ME/Research/Hands-On/flower_tutorial/client.py", line 53, in fit
    optim = torch.optim.SGD(self.get_parameters(config['config_fit']), lr=lr, momentum=momentum)
                                                ~~~~~~^^^^^^^^^^^^^^
  File "/home/mamatha/anaconda3/lib/python3.13/site-packages/flwr/common/record/typeddict.py", line 52, in __getitem__
    return cast(dict[K, V], self.__dict__["_data"])[item]
           ~~~~~~~~~~~~~~~~~~~~~~~~~~~~~~~~~~~~~~~~^^^^^^
KeyError: 'config_fit'

The above exception was the direct cause of the following exception:

[36mray::ClientAppActor.run()[39m (pid=9377, ip=10.100.14.161, actor_id=2ed9d15c180df5bc1221911e01000000, repr=<flwr.simulation.ray_transport.ray_actor.ClientAppActor object at 0x7fb7e4379010>)
  File "/home/mamatha/anaconda3/lib/python3.13/site-packages/flwr/simulation/ray_transport/ray_actor.py", line 64, in run
    raise ClientAppException(str(ex)) from ex
flwr.client.client_app.ClientAppException: 
Exception ClientAppException occurred. Message: 'config_fit'

[2025-10-16 10:40:10,685][flwr][ERROR] - [36mray::ClientAppActor.run()[39m (pid=9377, ip=10.100.14.161, actor_id=2ed9d15c180df5bc1221911e01000000, repr=<flwr.simulation.ray_transport.ray_actor.ClientAppActor object at 0x7fb7e4379010>)
  File "/home/mamatha/anaconda3/lib/python3.13/site-packages/flwr/client/client_app.py", line 144, in __call__
    return self._call(message, context)
           ~~~~~~~~~~^^^^^^^^^^^^^^^^^^
  File "/home/mamatha/anaconda3/lib/python3.13/site-packages/flwr/client/client_app.py", line 128, in ffn
    out_message = handle_legacy_message_from_msgtype(
        client_fn=client_fn, message=message, context=context
    )
  File "/home/mamatha/anaconda3/lib/python3.13/site-packages/flwr/client/message_handler/message_handler.py", line 128, in handle_legacy_message_from_msgtype
    fit_res = maybe_call_fit(
        client=client,
        fit_ins=recorddict_to_fitins(message.content, keep_input=True),
    )
  File "/home/mamatha/anaconda3/lib/python3.13/site-packages/flwr/client/client.py", line 224, in maybe_call_fit
    return client.fit(fit_ins)
           ~~~~~~~~~~^^^^^^^^^
  File "/home/mamatha/anaconda3/lib/python3.13/site-packages/flwr/client/numpy_client.py", line 227, in _fit
    results = self.numpy_client.fit(parameters, ins.config)  # type: ignore
  File "/home/mamatha/ME/Research/Hands-On/flower_tutorial/client.py", line 53, in fit
    optim = torch.optim.SGD(self.get_parameters(config['config_fit']), lr=lr, momentum=momentum)
                                                ~~~~~~^^^^^^^^^^^^^^
  File "/home/mamatha/anaconda3/lib/python3.13/site-packages/flwr/common/record/typeddict.py", line 52, in __getitem__
    return cast(dict[K, V], self.__dict__["_data"])[item]
           ~~~~~~~~~~~~~~~~~~~~~~~~~~~~~~~~~~~~~~~~^^^^^^
KeyError: 'config_fit'

The above exception was the direct cause of the following exception:

[36mray::ClientAppActor.run()[39m (pid=9377, ip=10.100.14.161, actor_id=2ed9d15c180df5bc1221911e01000000, repr=<flwr.simulation.ray_transport.ray_actor.ClientAppActor object at 0x7fb7e4379010>)
  File "/home/mamatha/anaconda3/lib/python3.13/site-packages/flwr/simulation/ray_transport/ray_actor.py", line 64, in run
    raise ClientAppException(str(ex)) from ex
flwr.client.client_app.ClientAppException: 
Exception ClientAppException occurred. Message: 'config_fit'
[2025-10-16 10:40:10,753][flwr][ERROR] - Traceback (most recent call last):
  File "/home/mamatha/anaconda3/lib/python3.13/site-packages/flwr/simulation/ray_transport/ray_client_proxy.py", line 95, in _submit_job
    out_mssg, updated_context = self.actor_pool.get_client_result(
                                ~~~~~~~~~~~~~~~~~~~~~~~~~~~~~~~~~^
        partition_id_str, timeout
        ^^^^^^^^^^^^^^^^^^^^^^^^^
    )
    ^
  File "/home/mamatha/anaconda3/lib/python3.13/site-packages/flwr/simulation/ray_transport/ray_actor.py", line 401, in get_client_result
    return self._fetch_future_result(cid)
           ~~~~~~~~~~~~~~~~~~~~~~~~~^^^^^
  File "/home/mamatha/anaconda3/lib/python3.13/site-packages/flwr/simulation/ray_transport/ray_actor.py", line 282, in _fetch_future_result
    res_cid, out_mssg, updated_context = ray.get(
                                         ~~~~~~~^
        future
        ^^^^^^
    )  # type: (str, Message, Context)
    ^
  File "/home/mamatha/anaconda3/lib/python3.13/site-packages/ray/_private/auto_init_hook.py", line 22, in auto_init_wrapper
    return fn(*args, **kwargs)
  File "/home/mamatha/anaconda3/lib/python3.13/site-packages/ray/_private/client_mode_hook.py", line 104, in wrapper
    return func(*args, **kwargs)
  File "/home/mamatha/anaconda3/lib/python3.13/site-packages/ray/_private/worker.py", line 2962, in get
    values, debugger_breakpoint = worker.get_objects(
                                  ~~~~~~~~~~~~~~~~~~^
        object_refs, timeout=timeout, _tensor_transport=_tensor_transport
        ^^^^^^^^^^^^^^^^^^^^^^^^^^^^^^^^^^^^^^^^^^^^^^^^^^^^^^^^^^^^^^^^^
    )
    ^
  File "/home/mamatha/anaconda3/lib/python3.13/site-packages/ray/_private/worker.py", line 1026, in get_objects
    raise value.as_instanceof_cause()
ray.exceptions.RayTaskError(ClientAppException): [36mray::ClientAppActor.run()[39m (pid=9378, ip=10.100.14.161, actor_id=c85f7b1d3bb50febc908d14201000000, repr=<flwr.simulation.ray_transport.ray_actor.ClientAppActor object at 0x7f9bc05c1010>)
  File "/home/mamatha/anaconda3/lib/python3.13/site-packages/flwr/client/client_app.py", line 144, in __call__
    return self._call(message, context)
           ~~~~~~~~~~^^^^^^^^^^^^^^^^^^
  File "/home/mamatha/anaconda3/lib/python3.13/site-packages/flwr/client/client_app.py", line 128, in ffn
    out_message = handle_legacy_message_from_msgtype(
        client_fn=client_fn, message=message, context=context
    )
  File "/home/mamatha/anaconda3/lib/python3.13/site-packages/flwr/client/message_handler/message_handler.py", line 128, in handle_legacy_message_from_msgtype
    fit_res = maybe_call_fit(
        client=client,
        fit_ins=recorddict_to_fitins(message.content, keep_input=True),
    )
  File "/home/mamatha/anaconda3/lib/python3.13/site-packages/flwr/client/client.py", line 224, in maybe_call_fit
    return client.fit(fit_ins)
           ~~~~~~~~~~^^^^^^^^^
  File "/home/mamatha/anaconda3/lib/python3.13/site-packages/flwr/client/numpy_client.py", line 227, in _fit
    results = self.numpy_client.fit(parameters, ins.config)  # type: ignore
  File "/home/mamatha/ME/Research/Hands-On/flower_tutorial/client.py", line 53, in fit
    optim = torch.optim.SGD(self.get_parameters(config['config_fit']), lr=lr, momentum=momentum)
                                                ~~~~~~^^^^^^^^^^^^^^
  File "/home/mamatha/anaconda3/lib/python3.13/site-packages/flwr/common/record/typeddict.py", line 52, in __getitem__
    return cast(dict[K, V], self.__dict__["_data"])[item]
           ~~~~~~~~~~~~~~~~~~~~~~~~~~~~~~~~~~~~~~~~^^^^^^
KeyError: 'config_fit'

The above exception was the direct cause of the following exception:

[36mray::ClientAppActor.run()[39m (pid=9378, ip=10.100.14.161, actor_id=c85f7b1d3bb50febc908d14201000000, repr=<flwr.simulation.ray_transport.ray_actor.ClientAppActor object at 0x7f9bc05c1010>)
  File "/home/mamatha/anaconda3/lib/python3.13/site-packages/flwr/simulation/ray_transport/ray_actor.py", line 64, in run
    raise ClientAppException(str(ex)) from ex
flwr.client.client_app.ClientAppException: 
Exception ClientAppException occurred. Message: 'config_fit'

[2025-10-16 10:40:10,753][flwr][ERROR] - [36mray::ClientAppActor.run()[39m (pid=9378, ip=10.100.14.161, actor_id=c85f7b1d3bb50febc908d14201000000, repr=<flwr.simulation.ray_transport.ray_actor.ClientAppActor object at 0x7f9bc05c1010>)
  File "/home/mamatha/anaconda3/lib/python3.13/site-packages/flwr/client/client_app.py", line 144, in __call__
    return self._call(message, context)
           ~~~~~~~~~~^^^^^^^^^^^^^^^^^^
  File "/home/mamatha/anaconda3/lib/python3.13/site-packages/flwr/client/client_app.py", line 128, in ffn
    out_message = handle_legacy_message_from_msgtype(
        client_fn=client_fn, message=message, context=context
    )
  File "/home/mamatha/anaconda3/lib/python3.13/site-packages/flwr/client/message_handler/message_handler.py", line 128, in handle_legacy_message_from_msgtype
    fit_res = maybe_call_fit(
        client=client,
        fit_ins=recorddict_to_fitins(message.content, keep_input=True),
    )
  File "/home/mamatha/anaconda3/lib/python3.13/site-packages/flwr/client/client.py", line 224, in maybe_call_fit
    return client.fit(fit_ins)
           ~~~~~~~~~~^^^^^^^^^
  File "/home/mamatha/anaconda3/lib/python3.13/site-packages/flwr/client/numpy_client.py", line 227, in _fit
    results = self.numpy_client.fit(parameters, ins.config)  # type: ignore
  File "/home/mamatha/ME/Research/Hands-On/flower_tutorial/client.py", line 53, in fit
    optim = torch.optim.SGD(self.get_parameters(config['config_fit']), lr=lr, momentum=momentum)
                                                ~~~~~~^^^^^^^^^^^^^^
  File "/home/mamatha/anaconda3/lib/python3.13/site-packages/flwr/common/record/typeddict.py", line 52, in __getitem__
    return cast(dict[K, V], self.__dict__["_data"])[item]
           ~~~~~~~~~~~~~~~~~~~~~~~~~~~~~~~~~~~~~~~~^^^^^^
KeyError: 'config_fit'

The above exception was the direct cause of the following exception:

[36mray::ClientAppActor.run()[39m (pid=9378, ip=10.100.14.161, actor_id=c85f7b1d3bb50febc908d14201000000, repr=<flwr.simulation.ray_transport.ray_actor.ClientAppActor object at 0x7f9bc05c1010>)
  File "/home/mamatha/anaconda3/lib/python3.13/site-packages/flwr/simulation/ray_transport/ray_actor.py", line 64, in run
    raise ClientAppException(str(ex)) from ex
flwr.client.client_app.ClientAppException: 
Exception ClientAppException occurred. Message: 'config_fit'
[2025-10-16 10:40:10,800][flwr][ERROR] - Traceback (most recent call last):
  File "/home/mamatha/anaconda3/lib/python3.13/site-packages/flwr/simulation/ray_transport/ray_client_proxy.py", line 95, in _submit_job
    out_mssg, updated_context = self.actor_pool.get_client_result(
                                ~~~~~~~~~~~~~~~~~~~~~~~~~~~~~~~~~^
        partition_id_str, timeout
        ^^^^^^^^^^^^^^^^^^^^^^^^^
    )
    ^
  File "/home/mamatha/anaconda3/lib/python3.13/site-packages/flwr/simulation/ray_transport/ray_actor.py", line 401, in get_client_result
    return self._fetch_future_result(cid)
           ~~~~~~~~~~~~~~~~~~~~~~~~~^^^^^
  File "/home/mamatha/anaconda3/lib/python3.13/site-packages/flwr/simulation/ray_transport/ray_actor.py", line 282, in _fetch_future_result
    res_cid, out_mssg, updated_context = ray.get(
                                         ~~~~~~~^
        future
        ^^^^^^
    )  # type: (str, Message, Context)
    ^
  File "/home/mamatha/anaconda3/lib/python3.13/site-packages/ray/_private/auto_init_hook.py", line 22, in auto_init_wrapper
    return fn(*args, **kwargs)
  File "/home/mamatha/anaconda3/lib/python3.13/site-packages/ray/_private/client_mode_hook.py", line 104, in wrapper
    return func(*args, **kwargs)
  File "/home/mamatha/anaconda3/lib/python3.13/site-packages/ray/_private/worker.py", line 2962, in get
    values, debugger_breakpoint = worker.get_objects(
                                  ~~~~~~~~~~~~~~~~~~^
        object_refs, timeout=timeout, _tensor_transport=_tensor_transport
        ^^^^^^^^^^^^^^^^^^^^^^^^^^^^^^^^^^^^^^^^^^^^^^^^^^^^^^^^^^^^^^^^^
    )
    ^
  File "/home/mamatha/anaconda3/lib/python3.13/site-packages/ray/_private/worker.py", line 1026, in get_objects
    raise value.as_instanceof_cause()
ray.exceptions.RayTaskError(ClientAppException): [36mray::ClientAppActor.run()[39m (pid=9371, ip=10.100.14.161, actor_id=5d13ecaffa1e47d9f8e66f0901000000, repr=<flwr.simulation.ray_transport.ray_actor.ClientAppActor object at 0x7f097c085010>)
  File "/home/mamatha/anaconda3/lib/python3.13/site-packages/flwr/client/client_app.py", line 144, in __call__
    return self._call(message, context)
           ~~~~~~~~~~^^^^^^^^^^^^^^^^^^
  File "/home/mamatha/anaconda3/lib/python3.13/site-packages/flwr/client/client_app.py", line 128, in ffn
    out_message = handle_legacy_message_from_msgtype(
        client_fn=client_fn, message=message, context=context
    )
  File "/home/mamatha/anaconda3/lib/python3.13/site-packages/flwr/client/message_handler/message_handler.py", line 128, in handle_legacy_message_from_msgtype
    fit_res = maybe_call_fit(
        client=client,
        fit_ins=recorddict_to_fitins(message.content, keep_input=True),
    )
  File "/home/mamatha/anaconda3/lib/python3.13/site-packages/flwr/client/client.py", line 224, in maybe_call_fit
    return client.fit(fit_ins)
           ~~~~~~~~~~^^^^^^^^^
  File "/home/mamatha/anaconda3/lib/python3.13/site-packages/flwr/client/numpy_client.py", line 227, in _fit
    results = self.numpy_client.fit(parameters, ins.config)  # type: ignore
  File "/home/mamatha/ME/Research/Hands-On/flower_tutorial/client.py", line 53, in fit
    optim = torch.optim.SGD(self.get_parameters(config['config_fit']), lr=lr, momentum=momentum)
                                                ~~~~~~^^^^^^^^^^^^^^
  File "/home/mamatha/anaconda3/lib/python3.13/site-packages/flwr/common/record/typeddict.py", line 52, in __getitem__
    return cast(dict[K, V], self.__dict__["_data"])[item]
           ~~~~~~~~~~~~~~~~~~~~~~~~~~~~~~~~~~~~~~~~^^^^^^
KeyError: 'config_fit'

The above exception was the direct cause of the following exception:

[36mray::ClientAppActor.run()[39m (pid=9371, ip=10.100.14.161, actor_id=5d13ecaffa1e47d9f8e66f0901000000, repr=<flwr.simulation.ray_transport.ray_actor.ClientAppActor object at 0x7f097c085010>)
  File "/home/mamatha/anaconda3/lib/python3.13/site-packages/flwr/simulation/ray_transport/ray_actor.py", line 64, in run
    raise ClientAppException(str(ex)) from ex
flwr.client.client_app.ClientAppException: 
Exception ClientAppException occurred. Message: 'config_fit'

[2025-10-16 10:40:10,800][flwr][ERROR] - [36mray::ClientAppActor.run()[39m (pid=9371, ip=10.100.14.161, actor_id=5d13ecaffa1e47d9f8e66f0901000000, repr=<flwr.simulation.ray_transport.ray_actor.ClientAppActor object at 0x7f097c085010>)
  File "/home/mamatha/anaconda3/lib/python3.13/site-packages/flwr/client/client_app.py", line 144, in __call__
    return self._call(message, context)
           ~~~~~~~~~~^^^^^^^^^^^^^^^^^^
  File "/home/mamatha/anaconda3/lib/python3.13/site-packages/flwr/client/client_app.py", line 128, in ffn
    out_message = handle_legacy_message_from_msgtype(
        client_fn=client_fn, message=message, context=context
    )
  File "/home/mamatha/anaconda3/lib/python3.13/site-packages/flwr/client/message_handler/message_handler.py", line 128, in handle_legacy_message_from_msgtype
    fit_res = maybe_call_fit(
        client=client,
        fit_ins=recorddict_to_fitins(message.content, keep_input=True),
    )
  File "/home/mamatha/anaconda3/lib/python3.13/site-packages/flwr/client/client.py", line 224, in maybe_call_fit
    return client.fit(fit_ins)
           ~~~~~~~~~~^^^^^^^^^
  File "/home/mamatha/anaconda3/lib/python3.13/site-packages/flwr/client/numpy_client.py", line 227, in _fit
    results = self.numpy_client.fit(parameters, ins.config)  # type: ignore
  File "/home/mamatha/ME/Research/Hands-On/flower_tutorial/client.py", line 53, in fit
    optim = torch.optim.SGD(self.get_parameters(config['config_fit']), lr=lr, momentum=momentum)
                                                ~~~~~~^^^^^^^^^^^^^^
  File "/home/mamatha/anaconda3/lib/python3.13/site-packages/flwr/common/record/typeddict.py", line 52, in __getitem__
    return cast(dict[K, V], self.__dict__["_data"])[item]
           ~~~~~~~~~~~~~~~~~~~~~~~~~~~~~~~~~~~~~~~~^^^^^^
KeyError: 'config_fit'

The above exception was the direct cause of the following exception:

[36mray::ClientAppActor.run()[39m (pid=9371, ip=10.100.14.161, actor_id=5d13ecaffa1e47d9f8e66f0901000000, repr=<flwr.simulation.ray_transport.ray_actor.ClientAppActor object at 0x7f097c085010>)
  File "/home/mamatha/anaconda3/lib/python3.13/site-packages/flwr/simulation/ray_transport/ray_actor.py", line 64, in run
    raise ClientAppException(str(ex)) from ex
flwr.client.client_app.ClientAppException: 
Exception ClientAppException occurred. Message: 'config_fit'
[2025-10-16 10:40:10,842][flwr][ERROR] - Traceback (most recent call last):
  File "/home/mamatha/anaconda3/lib/python3.13/site-packages/flwr/simulation/ray_transport/ray_client_proxy.py", line 95, in _submit_job
    out_mssg, updated_context = self.actor_pool.get_client_result(
                                ~~~~~~~~~~~~~~~~~~~~~~~~~~~~~~~~~^
        partition_id_str, timeout
        ^^^^^^^^^^^^^^^^^^^^^^^^^
    )
    ^
  File "/home/mamatha/anaconda3/lib/python3.13/site-packages/flwr/simulation/ray_transport/ray_actor.py", line 401, in get_client_result
    return self._fetch_future_result(cid)
           ~~~~~~~~~~~~~~~~~~~~~~~~~^^^^^
  File "/home/mamatha/anaconda3/lib/python3.13/site-packages/flwr/simulation/ray_transport/ray_actor.py", line 282, in _fetch_future_result
    res_cid, out_mssg, updated_context = ray.get(
                                         ~~~~~~~^
        future
        ^^^^^^
    )  # type: (str, Message, Context)
    ^
  File "/home/mamatha/anaconda3/lib/python3.13/site-packages/ray/_private/auto_init_hook.py", line 22, in auto_init_wrapper
    return fn(*args, **kwargs)
  File "/home/mamatha/anaconda3/lib/python3.13/site-packages/ray/_private/client_mode_hook.py", line 104, in wrapper
    return func(*args, **kwargs)
  File "/home/mamatha/anaconda3/lib/python3.13/site-packages/ray/_private/worker.py", line 2962, in get
    values, debugger_breakpoint = worker.get_objects(
                                  ~~~~~~~~~~~~~~~~~~^
        object_refs, timeout=timeout, _tensor_transport=_tensor_transport
        ^^^^^^^^^^^^^^^^^^^^^^^^^^^^^^^^^^^^^^^^^^^^^^^^^^^^^^^^^^^^^^^^^
    )
    ^
  File "/home/mamatha/anaconda3/lib/python3.13/site-packages/ray/_private/worker.py", line 1026, in get_objects
    raise value.as_instanceof_cause()
ray.exceptions.RayTaskError(ClientAppException): [36mray::ClientAppActor.run()[39m (pid=9368, ip=10.100.14.161, actor_id=4f1560cc22bfcb12703494fb01000000, repr=<flwr.simulation.ray_transport.ray_actor.ClientAppActor object at 0x7f4cb03d5010>)
  File "/home/mamatha/anaconda3/lib/python3.13/site-packages/flwr/client/client_app.py", line 144, in __call__
    return self._call(message, context)
           ~~~~~~~~~~^^^^^^^^^^^^^^^^^^
  File "/home/mamatha/anaconda3/lib/python3.13/site-packages/flwr/client/client_app.py", line 128, in ffn
    out_message = handle_legacy_message_from_msgtype(
        client_fn=client_fn, message=message, context=context
    )
  File "/home/mamatha/anaconda3/lib/python3.13/site-packages/flwr/client/message_handler/message_handler.py", line 128, in handle_legacy_message_from_msgtype
    fit_res = maybe_call_fit(
        client=client,
        fit_ins=recorddict_to_fitins(message.content, keep_input=True),
    )
  File "/home/mamatha/anaconda3/lib/python3.13/site-packages/flwr/client/client.py", line 224, in maybe_call_fit
    return client.fit(fit_ins)
           ~~~~~~~~~~^^^^^^^^^
  File "/home/mamatha/anaconda3/lib/python3.13/site-packages/flwr/client/numpy_client.py", line 227, in _fit
    results = self.numpy_client.fit(parameters, ins.config)  # type: ignore
  File "/home/mamatha/ME/Research/Hands-On/flower_tutorial/client.py", line 53, in fit
    optim = torch.optim.SGD(self.get_parameters(config['config_fit']), lr=lr, momentum=momentum)
                                                ~~~~~~^^^^^^^^^^^^^^
  File "/home/mamatha/anaconda3/lib/python3.13/site-packages/flwr/common/record/typeddict.py", line 52, in __getitem__
    return cast(dict[K, V], self.__dict__["_data"])[item]
           ~~~~~~~~~~~~~~~~~~~~~~~~~~~~~~~~~~~~~~~~^^^^^^
KeyError: 'config_fit'

The above exception was the direct cause of the following exception:

[36mray::ClientAppActor.run()[39m (pid=9368, ip=10.100.14.161, actor_id=4f1560cc22bfcb12703494fb01000000, repr=<flwr.simulation.ray_transport.ray_actor.ClientAppActor object at 0x7f4cb03d5010>)
  File "/home/mamatha/anaconda3/lib/python3.13/site-packages/flwr/simulation/ray_transport/ray_actor.py", line 64, in run
    raise ClientAppException(str(ex)) from ex
flwr.client.client_app.ClientAppException: 
Exception ClientAppException occurred. Message: 'config_fit'

[2025-10-16 10:40:10,842][flwr][ERROR] - [36mray::ClientAppActor.run()[39m (pid=9368, ip=10.100.14.161, actor_id=4f1560cc22bfcb12703494fb01000000, repr=<flwr.simulation.ray_transport.ray_actor.ClientAppActor object at 0x7f4cb03d5010>)
  File "/home/mamatha/anaconda3/lib/python3.13/site-packages/flwr/client/client_app.py", line 144, in __call__
    return self._call(message, context)
           ~~~~~~~~~~^^^^^^^^^^^^^^^^^^
  File "/home/mamatha/anaconda3/lib/python3.13/site-packages/flwr/client/client_app.py", line 128, in ffn
    out_message = handle_legacy_message_from_msgtype(
        client_fn=client_fn, message=message, context=context
    )
  File "/home/mamatha/anaconda3/lib/python3.13/site-packages/flwr/client/message_handler/message_handler.py", line 128, in handle_legacy_message_from_msgtype
    fit_res = maybe_call_fit(
        client=client,
        fit_ins=recorddict_to_fitins(message.content, keep_input=True),
    )
  File "/home/mamatha/anaconda3/lib/python3.13/site-packages/flwr/client/client.py", line 224, in maybe_call_fit
    return client.fit(fit_ins)
           ~~~~~~~~~~^^^^^^^^^
  File "/home/mamatha/anaconda3/lib/python3.13/site-packages/flwr/client/numpy_client.py", line 227, in _fit
    results = self.numpy_client.fit(parameters, ins.config)  # type: ignore
  File "/home/mamatha/ME/Research/Hands-On/flower_tutorial/client.py", line 53, in fit
    optim = torch.optim.SGD(self.get_parameters(config['config_fit']), lr=lr, momentum=momentum)
                                                ~~~~~~^^^^^^^^^^^^^^
  File "/home/mamatha/anaconda3/lib/python3.13/site-packages/flwr/common/record/typeddict.py", line 52, in __getitem__
    return cast(dict[K, V], self.__dict__["_data"])[item]
           ~~~~~~~~~~~~~~~~~~~~~~~~~~~~~~~~~~~~~~~~^^^^^^
KeyError: 'config_fit'

The above exception was the direct cause of the following exception:

[36mray::ClientAppActor.run()[39m (pid=9368, ip=10.100.14.161, actor_id=4f1560cc22bfcb12703494fb01000000, repr=<flwr.simulation.ray_transport.ray_actor.ClientAppActor object at 0x7f4cb03d5010>)
  File "/home/mamatha/anaconda3/lib/python3.13/site-packages/flwr/simulation/ray_transport/ray_actor.py", line 64, in run
    raise ClientAppException(str(ex)) from ex
flwr.client.client_app.ClientAppException: 
Exception ClientAppException occurred. Message: 'config_fit'
[2025-10-16 10:40:10,842][flwr][INFO] - aggregate_fit: received 0 results and 10 failures
[2025-10-16 10:40:11,322][flwr][INFO] - fit progress: (1, 182.12883377075195, {'accuracy': 0.1026}, 2.3718431930001316)
[2025-10-16 10:40:11,322][flwr][INFO] - configure_evaluate: strategy sampled 25 clients (out of 100)
[2025-10-16 10:40:14,147][flwr][INFO] - aggregate_evaluate: received 25 results and 0 failures
[2025-10-16 10:40:14,147][flwr][WARNING] - No evaluate_metrics_aggregation_fn provided
[2025-10-16 10:40:14,147][flwr][INFO] - 
[2025-10-16 10:40:14,147][flwr][INFO] - [SUMMARY]
[2025-10-16 10:40:14,147][flwr][INFO] - Run finished 1 round(s) in 5.20s
[2025-10-16 10:40:14,147][flwr][INFO] - 	History (loss, distributed):
[2025-10-16 10:40:14,147][flwr][INFO] - 		round 1: 6.91734658241272
[2025-10-16 10:40:14,147][flwr][INFO] - 	History (loss, centralized):
[2025-10-16 10:40:14,147][flwr][INFO] - 		round 0: 182.12883377075195
[2025-10-16 10:40:14,147][flwr][INFO] - 		round 1: 182.12883377075195
[2025-10-16 10:40:14,147][flwr][INFO] - 	History (metrics, centralized):
[2025-10-16 10:40:14,147][flwr][INFO] - 	{'accuracy': [(0, 0.1026), (1, 0.1026)]}
[2025-10-16 10:40:14,147][flwr][INFO] - 
