[2025-10-15 13:26:51,574][flwr][WARNING] - DEPRECATED FEATURE: flwr.simulation.start_simulation() is deprecated.
	Instead, use the `flwr run` CLI command to start a local simulation in your Flower app, as shown for example below:

		$ flwr new  # Create a new Flower app from a template

		$ flwr run  # Run the Flower app in Simulation Mode

	Using `start_simulation()` is deprecated.

            This is a deprecated feature. It will be removed
            entirely in future versions of Flower.
        
[2025-10-15 13:26:51,575][flwr][INFO] - Starting Flower simulation, config: num_rounds=5, no round_timeout
[2025-10-15 13:26:52,936][flwr][INFO] - Flower VCE: Ray initialized with resources: {'CPU': 20.0, 'node:__internal_head__': 1.0, 'object_store_memory': 8157813964.0, 'memory': 19034899252.0, 'node:10.100.14.161': 1.0}
[2025-10-15 13:26:52,937][flwr][INFO] - Optimize your simulation with Flower VCE: https://flower.ai/docs/framework/how-to-run-simulations.html
[2025-10-15 13:26:52,937][flwr][INFO] - No `client_resources` specified. Using minimal resources for clients.
[2025-10-15 13:26:52,937][flwr][INFO] - Flower VCE: Resources for each Virtual Client: {'num_cpus': 1, 'num_gpus': 0.0}
[2025-10-15 13:26:52,981][flwr][INFO] - Flower VCE: Creating VirtualClientEngineActorPool with 20 actors
[2025-10-15 13:26:52,982][flwr][INFO] - [INIT]
[2025-10-15 13:26:52,982][flwr][INFO] - Requesting initial parameters from one random client
[2025-10-15 13:26:54,329][flwr][ERROR] - Traceback (most recent call last):
  File "/home/mamatha/anaconda3/lib/python3.13/site-packages/flwr/simulation/ray_transport/ray_client_proxy.py", line 95, in _submit_job
    out_mssg, updated_context = self.actor_pool.get_client_result(
                                ~~~~~~~~~~~~~~~~~~~~~~~~~~~~~~~~~^
        partition_id_str, timeout
        ^^^^^^^^^^^^^^^^^^^^^^^^^
    )
    ^
  File "/home/mamatha/anaconda3/lib/python3.13/site-packages/flwr/simulation/ray_transport/ray_actor.py", line 401, in get_client_result
    return self._fetch_future_result(cid)
           ~~~~~~~~~~~~~~~~~~~~~~~~~^^^^^
  File "/home/mamatha/anaconda3/lib/python3.13/site-packages/flwr/simulation/ray_transport/ray_actor.py", line 282, in _fetch_future_result
    res_cid, out_mssg, updated_context = ray.get(
                                         ~~~~~~~^
        future
        ^^^^^^
    )  # type: (str, Message, Context)
    ^
  File "/home/mamatha/anaconda3/lib/python3.13/site-packages/ray/_private/auto_init_hook.py", line 22, in auto_init_wrapper
    return fn(*args, **kwargs)
  File "/home/mamatha/anaconda3/lib/python3.13/site-packages/ray/_private/client_mode_hook.py", line 104, in wrapper
    return func(*args, **kwargs)
  File "/home/mamatha/anaconda3/lib/python3.13/site-packages/ray/_private/worker.py", line 2962, in get
    values, debugger_breakpoint = worker.get_objects(
                                  ~~~~~~~~~~~~~~~~~~^
        object_refs, timeout=timeout, _tensor_transport=_tensor_transport
        ^^^^^^^^^^^^^^^^^^^^^^^^^^^^^^^^^^^^^^^^^^^^^^^^^^^^^^^^^^^^^^^^^
    )
    ^
  File "/home/mamatha/anaconda3/lib/python3.13/site-packages/ray/_private/worker.py", line 1026, in get_objects
    raise value.as_instanceof_cause()
ray.exceptions.RayTaskError(ClientAppException): [36mray::ClientAppActor.run()[39m (pid=13178, ip=10.100.14.161, actor_id=06c22c37ff107877f7fd7bfe01000000, repr=<flwr.simulation.ray_transport.ray_actor.ClientAppActor object at 0x7f2dd8361010>)
  File "/home/mamatha/anaconda3/lib/python3.13/site-packages/flwr/client/client_app.py", line 144, in __call__
    return self._call(message, context)
           ~~~~~~~~~~^^^^^^^^^^^^^^^^^^
  File "/home/mamatha/anaconda3/lib/python3.13/site-packages/flwr/client/client_app.py", line 128, in ffn
    out_message = handle_legacy_message_from_msgtype(
        client_fn=client_fn, message=message, context=context
    )
  File "/home/mamatha/anaconda3/lib/python3.13/site-packages/flwr/client/message_handler/message_handler.py", line 96, in handle_legacy_message_from_msgtype
    client = client_fn(context)
  File "/home/mamatha/anaconda3/lib/python3.13/site-packages/flwr/client/client_app.py", line 72, in adaptor_fn
    return client_fn(str(cid))  # type: ignore
  File "/home/mamatha/ME/Research/Hands-On/flower_tutorial/client.py", line 69, in client_fn
    return FlowerClient(trainloader=trainloaders[int(cid)],
                        valloader=valloaders[int(cid)],
                        num_classes=num_classes,
    )
  File "/home/mamatha/ME/Research/Hands-On/flower_tutorial/client.py", line 15, in __init__
    super()._init()
    ^^^^^^^^^^^^^
AttributeError: 'super' object has no attribute '_init'

The above exception was the direct cause of the following exception:

[36mray::ClientAppActor.run()[39m (pid=13178, ip=10.100.14.161, actor_id=06c22c37ff107877f7fd7bfe01000000, repr=<flwr.simulation.ray_transport.ray_actor.ClientAppActor object at 0x7f2dd8361010>)
  File "/home/mamatha/anaconda3/lib/python3.13/site-packages/flwr/simulation/ray_transport/ray_actor.py", line 64, in run
    raise ClientAppException(str(ex)) from ex
flwr.client.client_app.ClientAppException: 
Exception ClientAppException occurred. Message: 'super' object has no attribute '_init'

[2025-10-15 13:26:54,329][flwr][ERROR] - [36mray::ClientAppActor.run()[39m (pid=13178, ip=10.100.14.161, actor_id=06c22c37ff107877f7fd7bfe01000000, repr=<flwr.simulation.ray_transport.ray_actor.ClientAppActor object at 0x7f2dd8361010>)
  File "/home/mamatha/anaconda3/lib/python3.13/site-packages/flwr/client/client_app.py", line 144, in __call__
    return self._call(message, context)
           ~~~~~~~~~~^^^^^^^^^^^^^^^^^^
  File "/home/mamatha/anaconda3/lib/python3.13/site-packages/flwr/client/client_app.py", line 128, in ffn
    out_message = handle_legacy_message_from_msgtype(
        client_fn=client_fn, message=message, context=context
    )
  File "/home/mamatha/anaconda3/lib/python3.13/site-packages/flwr/client/message_handler/message_handler.py", line 96, in handle_legacy_message_from_msgtype
    client = client_fn(context)
  File "/home/mamatha/anaconda3/lib/python3.13/site-packages/flwr/client/client_app.py", line 72, in adaptor_fn
    return client_fn(str(cid))  # type: ignore
  File "/home/mamatha/ME/Research/Hands-On/flower_tutorial/client.py", line 69, in client_fn
    return FlowerClient(trainloader=trainloaders[int(cid)],
                        valloader=valloaders[int(cid)],
                        num_classes=num_classes,
    )
  File "/home/mamatha/ME/Research/Hands-On/flower_tutorial/client.py", line 15, in __init__
    super()._init()
    ^^^^^^^^^^^^^
AttributeError: 'super' object has no attribute '_init'

The above exception was the direct cause of the following exception:

[36mray::ClientAppActor.run()[39m (pid=13178, ip=10.100.14.161, actor_id=06c22c37ff107877f7fd7bfe01000000, repr=<flwr.simulation.ray_transport.ray_actor.ClientAppActor object at 0x7f2dd8361010>)
  File "/home/mamatha/anaconda3/lib/python3.13/site-packages/flwr/simulation/ray_transport/ray_actor.py", line 64, in run
    raise ClientAppException(str(ex)) from ex
flwr.client.client_app.ClientAppException: 
Exception ClientAppException occurred. Message: 'super' object has no attribute '_init'
[2025-10-15 13:26:54,330][flwr][ERROR] - [36mray::ClientAppActor.run()[39m (pid=13178, ip=10.100.14.161, actor_id=06c22c37ff107877f7fd7bfe01000000, repr=<flwr.simulation.ray_transport.ray_actor.ClientAppActor object at 0x7f2dd8361010>)
  File "/home/mamatha/anaconda3/lib/python3.13/site-packages/flwr/client/client_app.py", line 144, in __call__
    return self._call(message, context)
           ~~~~~~~~~~^^^^^^^^^^^^^^^^^^
  File "/home/mamatha/anaconda3/lib/python3.13/site-packages/flwr/client/client_app.py", line 128, in ffn
    out_message = handle_legacy_message_from_msgtype(
        client_fn=client_fn, message=message, context=context
    )
  File "/home/mamatha/anaconda3/lib/python3.13/site-packages/flwr/client/message_handler/message_handler.py", line 96, in handle_legacy_message_from_msgtype
    client = client_fn(context)
  File "/home/mamatha/anaconda3/lib/python3.13/site-packages/flwr/client/client_app.py", line 72, in adaptor_fn
    return client_fn(str(cid))  # type: ignore
  File "/home/mamatha/ME/Research/Hands-On/flower_tutorial/client.py", line 69, in client_fn
    return FlowerClient(trainloader=trainloaders[int(cid)],
                        valloader=valloaders[int(cid)],
                        num_classes=num_classes,
    )
  File "/home/mamatha/ME/Research/Hands-On/flower_tutorial/client.py", line 15, in __init__
    super()._init()
    ^^^^^^^^^^^^^
AttributeError: 'super' object has no attribute '_init'

The above exception was the direct cause of the following exception:

[36mray::ClientAppActor.run()[39m (pid=13178, ip=10.100.14.161, actor_id=06c22c37ff107877f7fd7bfe01000000, repr=<flwr.simulation.ray_transport.ray_actor.ClientAppActor object at 0x7f2dd8361010>)
  File "/home/mamatha/anaconda3/lib/python3.13/site-packages/flwr/simulation/ray_transport/ray_actor.py", line 64, in run
    raise ClientAppException(str(ex)) from ex
flwr.client.client_app.ClientAppException: 
Exception ClientAppException occurred. Message: 'super' object has no attribute '_init'
[2025-10-15 13:26:54,331][flwr][ERROR] - Traceback (most recent call last):
  File "/home/mamatha/anaconda3/lib/python3.13/site-packages/flwr/simulation/legacy_app.py", line 361, in start_simulation
    hist = run_fl(
        server=initialized_server,
        config=initialized_config,
    )
  File "/home/mamatha/anaconda3/lib/python3.13/site-packages/flwr/server/server.py", line 492, in run_fl
    hist, elapsed_time = server.fit(
                         ~~~~~~~~~~^
        num_rounds=config.num_rounds, timeout=config.round_timeout
        ^^^^^^^^^^^^^^^^^^^^^^^^^^^^^^^^^^^^^^^^^^^^^^^^^^^^^^^^^^
    )
    ^
  File "/home/mamatha/anaconda3/lib/python3.13/site-packages/flwr/server/server.py", line 93, in fit
    self.parameters = self._get_initial_parameters(server_round=0, timeout=timeout)
                      ~~~~~~~~~~~~~~~~~~~~~~~~~~~~^^^^^^^^^^^^^^^^^^^^^^^^^^^^^^^^^
  File "/home/mamatha/anaconda3/lib/python3.13/site-packages/flwr/server/server.py", line 284, in _get_initial_parameters
    get_parameters_res = random_client.get_parameters(
        ins=ins, timeout=timeout, group_id=server_round
    )
  File "/home/mamatha/anaconda3/lib/python3.13/site-packages/flwr/simulation/ray_transport/ray_client_proxy.py", line 170, in get_parameters
    message_out = self._submit_job(message, timeout)
  File "/home/mamatha/anaconda3/lib/python3.13/site-packages/flwr/simulation/ray_transport/ray_client_proxy.py", line 109, in _submit_job
    raise ex
  File "/home/mamatha/anaconda3/lib/python3.13/site-packages/flwr/simulation/ray_transport/ray_client_proxy.py", line 95, in _submit_job
    out_mssg, updated_context = self.actor_pool.get_client_result(
                                ~~~~~~~~~~~~~~~~~~~~~~~~~~~~~~~~~^
        partition_id_str, timeout
        ^^^^^^^^^^^^^^^^^^^^^^^^^
    )
    ^
  File "/home/mamatha/anaconda3/lib/python3.13/site-packages/flwr/simulation/ray_transport/ray_actor.py", line 401, in get_client_result
    return self._fetch_future_result(cid)
           ~~~~~~~~~~~~~~~~~~~~~~~~~^^^^^
  File "/home/mamatha/anaconda3/lib/python3.13/site-packages/flwr/simulation/ray_transport/ray_actor.py", line 282, in _fetch_future_result
    res_cid, out_mssg, updated_context = ray.get(
                                         ~~~~~~~^
        future
        ^^^^^^
    )  # type: (str, Message, Context)
    ^
  File "/home/mamatha/anaconda3/lib/python3.13/site-packages/ray/_private/auto_init_hook.py", line 22, in auto_init_wrapper
    return fn(*args, **kwargs)
  File "/home/mamatha/anaconda3/lib/python3.13/site-packages/ray/_private/client_mode_hook.py", line 104, in wrapper
    return func(*args, **kwargs)
  File "/home/mamatha/anaconda3/lib/python3.13/site-packages/ray/_private/worker.py", line 2962, in get
    values, debugger_breakpoint = worker.get_objects(
                                  ~~~~~~~~~~~~~~~~~~^
        object_refs, timeout=timeout, _tensor_transport=_tensor_transport
        ^^^^^^^^^^^^^^^^^^^^^^^^^^^^^^^^^^^^^^^^^^^^^^^^^^^^^^^^^^^^^^^^^
    )
    ^
  File "/home/mamatha/anaconda3/lib/python3.13/site-packages/ray/_private/worker.py", line 1026, in get_objects
    raise value.as_instanceof_cause()
ray.exceptions.RayTaskError(ClientAppException): [36mray::ClientAppActor.run()[39m (pid=13178, ip=10.100.14.161, actor_id=06c22c37ff107877f7fd7bfe01000000, repr=<flwr.simulation.ray_transport.ray_actor.ClientAppActor object at 0x7f2dd8361010>)
  File "/home/mamatha/anaconda3/lib/python3.13/site-packages/flwr/client/client_app.py", line 144, in __call__
    return self._call(message, context)
           ~~~~~~~~~~^^^^^^^^^^^^^^^^^^
  File "/home/mamatha/anaconda3/lib/python3.13/site-packages/flwr/client/client_app.py", line 128, in ffn
    out_message = handle_legacy_message_from_msgtype(
        client_fn=client_fn, message=message, context=context
    )
  File "/home/mamatha/anaconda3/lib/python3.13/site-packages/flwr/client/message_handler/message_handler.py", line 96, in handle_legacy_message_from_msgtype
    client = client_fn(context)
  File "/home/mamatha/anaconda3/lib/python3.13/site-packages/flwr/client/client_app.py", line 72, in adaptor_fn
    return client_fn(str(cid))  # type: ignore
  File "/home/mamatha/ME/Research/Hands-On/flower_tutorial/client.py", line 69, in client_fn
    return FlowerClient(trainloader=trainloaders[int(cid)],
                        valloader=valloaders[int(cid)],
                        num_classes=num_classes,
    )
  File "/home/mamatha/ME/Research/Hands-On/flower_tutorial/client.py", line 15, in __init__
    super()._init()
    ^^^^^^^^^^^^^
AttributeError: 'super' object has no attribute '_init'

The above exception was the direct cause of the following exception:

[36mray::ClientAppActor.run()[39m (pid=13178, ip=10.100.14.161, actor_id=06c22c37ff107877f7fd7bfe01000000, repr=<flwr.simulation.ray_transport.ray_actor.ClientAppActor object at 0x7f2dd8361010>)
  File "/home/mamatha/anaconda3/lib/python3.13/site-packages/flwr/simulation/ray_transport/ray_actor.py", line 64, in run
    raise ClientAppException(str(ex)) from ex
flwr.client.client_app.ClientAppException: 
Exception ClientAppException occurred. Message: 'super' object has no attribute '_init'

[2025-10-15 13:26:54,331][flwr][ERROR] - Your simulation crashed :(. This could be because of several reasons. The most common are: 
	 > Sometimes, issues in the simulation code itself can cause crashes. It's always a good idea to double-check your code for any potential bugs or inconsistencies that might be contributing to the problem. For example: 
		 - You might be using a class attribute in your clients that hasn't been defined.
		 - There could be an incorrect method call to a 3rd party library (e.g., PyTorch).
		 - The return types of methods in your clients/strategies might be incorrect.
	 > Your system couldn't fit a single VirtualClient: try lowering `client_resources`.
	 > All the actors in your pool crashed. This could be because: 
		 - You clients hit an out-of-memory (OOM) error and actors couldn't recover from it. Try launching your simulation with more generous `client_resources` setting (i.e. it seems {'num_cpus': 1, 'num_gpus': 0.0} is not enough for your run). Use fewer concurrent actors. 
		 - You were running a multi-node simulation and all worker nodes disconnected. The head node might still be alive but cannot accommodate any actor with resources: {'num_cpus': 1, 'num_gpus': 0.0}.
Take a look at the Flower simulation examples for guidance <https://flower.ai/docs/framework/how-to-run-simulations.html>.
